<?xml version='1.0' encoding='utf-8'?>
<mujoco model="wheel_leg">
  <default>
    <geom contype="1" conaffinity="0"/>
  </default>
  <compiler angle="radian" meshdir="meshes/" />
  
  <asset>
    <mesh name="base_link" file="base_link.STL" />
    <mesh name="left_leg_hip1_link" file="left_leg_hip1_link.STL" />
    <mesh name="left_leg_knee_link" file="left_leg_knee_link.STL" />
    <mesh name="left_leg_wheel_link" file="left_leg_wheel_link.STL" />
    <mesh name="left_leg_hip2_link" file="left_leg_hip2_link.STL" />
    <mesh name="left_leg_knee_father1_link" file="left_leg_knee_father1_link.STL" />
    <mesh name="left_leg_knee_father2_link" file="left_leg_knee_father2_link.STL" />
    <mesh name="left_leg_knee_father3_link" file="left_leg_knee_father3_link.STL" />
    
    <mesh name="right_leg_hip1_link" file="right_leg_hip1_link.STL" />
    <mesh name="right_leg_knee_link" file="right_leg_knee_link.STL" />
    <mesh name="right_leg_wheel_link" file="right_leg_wheel_link.STL" />
    <mesh name="right_leg_hip2_link" file="right_leg_hip2_link.STL" />
    <mesh name="right_leg_knee_father1_link" file="right_leg_knee_father1_link.STL" />
    <mesh name="right_leg_knee_father2_link" file="right_leg_knee_father2_link.STL" />
    <mesh name="right_leg_knee_father3_link" file="right_leg_knee_father3_link.STL" />
  </asset>
  
  <worldbody>
    <body name="base_link" pos="0 0 0.4">
      <freejoint name="root_joint"/>
      <inertial pos="-0.00746094 0.00090321 0.00604838" mass="16.54216288" fullinertia="0.41748778 0.41356974 0.49536783 0.00046838 0.01213606 -0.00410317" />
      <geom type="mesh" rgba="0.75294 0.75294 0.75294 1" mesh="base_link" />
      
      <body name="left_leg_hip1_link" pos="0 0.187 0">
        <inertial pos="-0.086207 -0.0093081 -0.0071445" mass="0.53238" fullinertia="0.00028513 0.0035718 0.0033255 3.881e-05 -0.00016116 -4.2e-07" />
        <joint name="left_leg_hip1_joint" pos="0 0 0" axis="0 -1 0" damping="0.1" />
        <site name="left_loop_site_hip1" pos="-0.11304 0 -0.00906" size="0.005" rgba="1 0 0 1"/>
        <geom type="mesh" rgba="0.75294 0.75294 0.75294 1" mesh="left_leg_hip1_link" />
        
        <body name="left_leg_knee_link" pos="-0.20933 0 -0.016769">
          <inertial pos="0.06010178 0.00644376 -0.04165431" mass="0.34933979" fullinertia="0.00107659 0.00354276 0.00251609 -9.93e-06 0.00150980 1.318e-05" />
          <joint name="left_leg_knee_joint" pos="0 0 0" axis="0 1 0" damping="0.05" />
          <site name="left_loop_site_knee" pos="-0.04553 0 0.04915" size="0.005" rgba="1 0 0 1"/>
          <geom type="mesh" rgba="0.75294 0.75294 0.75294 1" mesh="left_leg_knee_link" />
          
          <body name="left_leg_wheel_link" pos="0.2111 0 -0.135">
            <inertial pos="0.00020765 0.030642 -0.00012623" mass="0.28258" fullinertia="0.00029613 0.00053291 0.00029565 6.6e-07 -4.4e-07 -3.9e-07" />
            <joint name="left_leg_wheel_joint" pos="0 0 0" axis="0 1 0" damping="0.01" />
            <geom type="mesh" rgba="0.75294 0.75294 0.75294 1" mesh="left_leg_wheel_link" />
          </body>
        </body>
      </body>
      
      <body name="left_leg_hip2_link" pos="0 0.187 0">
        <inertial pos="0.027043 -0.0063817 -0.0015296" mass="0.12267" fullinertia="6.524e-05 0.0002766 0.00025765 -3.832e-05 1.092e-05 2.17e-06" />
        <joint name="left_leg_hip2_joint" pos="0 0 0" axis="0 1 0" damping="0.1" />
        <geom type="mesh" rgba="0.75294 0.75294 0.75294 1" mesh="left_leg_hip2_link" />
        
        <body name="left_leg_knee_father1_link" pos="0.11322 0 -0.0064037">
          <inertial pos="-0.052695 -0.0035417 -0.042635" mass="0.028977" fullinertia="2.2144e-05 6.947e-05 4.7639e-05 -1.7925e-08 -3.0736e-05 2.684e-08" />
          <joint name="left_leg_knee_father1_joint" pos="0 0 0" axis="0 1 0" damping="0.02" />
          <geom type="mesh" rgba="1 1 1 1" mesh="left_leg_knee_father1_link" />
          
          <body name="left_leg_knee_father2_link" pos="-0.11227 0 -0.074976">
            <inertial pos="-0.083089 0.0049101 0.056116" mass="0.04884" fullinertia="7.9882e-05 0.00020875 0.00012937 -3.5508e-08 9.7996e-05 3.7273e-08" />
            <joint name="left_leg_knee_father2_joint" pos="0 0 0" axis="0 1 0" damping="0.02" />
            <site name="left_loop_site_father2" pos="-0.11399 0 0.07232" size="0.005" rgba="1 0 0 1"/>
            <geom type="mesh" rgba="1 1 1 1" mesh="left_leg_knee_father2_link" />
            
            <body name="left_leg_knee_father3_link" pos="-0.15952 0 0.12148">
              <inertial pos="-0.048146 -0.0040765 -0.0038569" mass="0.020187" fullinertia="1.0501e-06 2.6055e-05 2.5224e-05 0 -1.949e-06 0" />
              <joint name="left_leg_knee_father3_joint" pos="0 0 0" axis="0 1 0" damping="0.02" />
              <site name="left_loop_site_father3" pos="-0.09629 0 -0.00771" size="0.005" rgba="1 0 0 1"/>
              <geom type="mesh" rgba="1 1 1 1" mesh="left_leg_knee_father3_link" />
            </body>
          </body>
        </body>
      </body>
      
      <body name="right_leg_hip1_link" pos="0 -0.188 0">
        <inertial pos="-0.086207 0.010308 -0.0071445" mass="0.53238" fullinertia="0.00028513 0.0035718 0.0033255 -3.881e-05 -0.00016116 4.2e-07" />
        <joint name="right_leg_hip1_joint" pos="0 0 0" axis="0 1 0" damping="0.1" />
        <site name="right_loop_site_hip1" pos="-0.11304 0 -0.00906" size="0.005" rgba="1 0 0 1"/>
        <geom type="mesh" rgba="0.75294 0.75294 0.75294 1" mesh="right_leg_hip1_link" />
        
        <body name="right_leg_knee_link" pos="-0.20933 0 -0.016769">
          <inertial pos="0.06010178 -0.00544376 -0.04165431" mass="0.34934" fullinertia="0.00107659 0.00354276 0.00251609 9.93e-06 0.0015098 -1.318e-05" />
          <joint name="right_leg_knee_joint" pos="0 0 0" axis="0 -1 0" damping="0.05" />
          <site name="right_loop_site_knee" pos="-0.04553 0 0.04915" size="0.005" rgba="1 0 0 1"/>
          <geom type="mesh" rgba="0.75294 0.75294 0.75294 1" mesh="right_leg_knee_link" />
          
          <body name="right_leg_wheel_link" pos="0.2111 0 -0.135">
            <inertial pos="0.00019389 -0.02535964 -0.00010647" mass="0.36500947" fullinertia="0.00033416 0.00055017 0.00033351 -4.9e-07 -4.8e-07 2.6e-07" />
            <joint name="right_leg_wheel_joint" pos="0 0 0" axis="0 -1 0" damping="0.01" />
            <geom type="mesh" rgba="0.75294 0.75294 0.75294 1" mesh="right_leg_wheel_link" />
          </body>
        </body>
      </body>
      
      <body name="right_leg_hip2_link" pos="0 -0.188 0">
        <inertial pos="0.027043 0.0073817 -0.0015296" mass="0.12267" fullinertia="6.524e-05 0.0002766 0.00025765 3.832e-05 1.092e-05 -2.17e-06" />
        <joint name="right_leg_hip2_joint" pos="0 0 0" axis="0 -1 0" damping="0.1" />
        <geom type="mesh" rgba="0.75294 0.75294 0.75294 1" mesh="right_leg_hip2_link" />
        
        <body name="right_leg_knee_father1_link" pos="0.11322 0 -0.0064037">
          <inertial pos="-0.052695 0.0045417 -0.042635" mass="0.028977" fullinertia="2.2144e-05 6.947e-05 4.7639e-05 1.7925e-08 -3.0736e-05 -2.684e-08" />
          <joint name="right_leg_knee_father1_joint" pos="0 0 0" axis="0 -1 0" damping="0.02" />
          <geom type="mesh" rgba="1 1 1 1" mesh="right_leg_knee_father1_link" />
          
          <body name="right_leg_knee_father2_link" pos="-0.11227 0 -0.074976">
            <inertial pos="-0.083089 -0.0039101 0.056116" mass="0.04884" fullinertia="7.9882e-05 0.00020875 0.00012937 3.5508e-08 9.7996e-05 -3.7273e-08" />
            <joint name="right_leg_knee_father2_joint" pos="0 0 0" axis="0 -1 0" damping="0.02" />
            <site name="right_loop_site_father2" pos="-0.11399 0 0.07232" size="0.005" rgba="1 0 0 1"/>
            <geom type="mesh" rgba="1 1 1 1" mesh="right_leg_knee_father2_link" />
            
            <body name="right_leg_knee_father3_link" pos="-0.15952 0 0.12148">
              <inertial pos="-0.048146 0.0050765 -0.0038569" mass="0.020187" fullinertia="1.0501e-06 2.6055e-05 2.5224e-05 0 -1.949e-06 0" />
              <joint name="right_leg_knee_father3_joint" pos="0 0 0" axis="0 -1 0" damping="0.02" />
              <site name="right_loop_site_father3" pos="-0.09629 0 -0.00771" size="0.005" rgba="1 0 0 1"/>
              <geom type="mesh" rgba="1 1 1 1" mesh="right_leg_knee_father3_link" />
            </body>
          </body>
        </body>
      </body>
      
    </body>
  </worldbody>
  
  <equality>
    <connect name="left_leg_loop1" site1="left_loop_site_hip1" site2="left_loop_site_father2" solref="0.001 1" solimp="0.99 0.99 0.01 0.5 2"/>
    <connect name="left_leg_loop2" site1="left_loop_site_knee" site2="left_loop_site_father3" solref="0.001 1" solimp="0.99 0.99 0.01 0.5 2"/>
    <connect name="right_leg_loop1" site1="right_loop_site_hip1" site2="right_loop_site_father2" solref="0.001 1" solimp="0.99 0.99 0.01 0.5 2"/>
    <connect name="right_leg_loop2" site1="right_loop_site_knee" site2="right_loop_site_father3" solref="0.001 1" solimp="0.99 0.99 0.01 0.5 2"/>
  </equality>

  <actuator>
    <general name="left_hip1_motor" joint="left_leg_hip1_joint" gainprm="1" ctrlrange="-30 30" />
    <general name="left_hip2_motor" joint="left_leg_hip2_joint" gainprm="1" ctrlrange="-30 30" />
    <general name="left_wheel_motor" joint="left_leg_wheel_joint" gainprm="1" ctrlrange="-10 10" />
    
    <general name="right_hip1_motor" joint="right_leg_hip1_joint" gainprm="1" ctrlrange="-30 30" />
    <general name="right_hip2_motor" joint="right_leg_hip2_joint" gainprm="1" ctrlrange="-30 30" />
    <general name="right_wheel_motor" joint="right_leg_wheel_joint" gainprm="1" ctrlrange="-10 10" />
  </actuator>
  
</mujoco>